package com.nx.netty.heima.day02;

import io.netty.channel.DefaultEventLoop;
import io.netty.util.concurrent.DefaultPromise;
import lombok.extern.slf4j.Slf4j;

import java.util.concurrent.ExecutionException;

@Slf4j
public class Future3 {

    //同步处理任务失败 - sync & get
    public static void main(String[] args) throws ExecutionException, InterruptedException {
        DefaultEventLoop eventExecutors = new DefaultEventLoop();
        DefaultPromise<Integer> promise = new DefaultPromise<>(eventExecutors);

        eventExecutors.execute(() ->{
            try {
                Thread.sleep(100);
            } catch (InterruptedException e) {
                e.printStackTrace();
            }
            RuntimeException e = new RuntimeException("error...");
            log.debug("set failure, {}", e.toString());
            promise.setFailure(e);
        });

        log.debug("start...");
        log.debug("{}", promise.getNow());
        // sync() 也会出现异常，只是 get 会再用 ExecutionException 包一层异常
        promise.get();
    }

}
